Failure # 1 (occurred at 2023-04-15_15-29-14)
[36mray::ImplicitFunc.train()[39m (pid=27200, ip=127.0.0.1, repr=objective)
  File "python\ray\_raylet.pyx", line 857, in ray._raylet.execute_task
  File "python\ray\_raylet.pyx", line 861, in ray._raylet.execute_task
  File "python\ray\_raylet.pyx", line 803, in ray._raylet.execute_task.function_executor
  File "C:\Users\manue\anaconda3\lib\site-packages\ray\_private\function_manager.py", line 674, in actor_method_executor
    return method(__ray_actor, *args, **kwargs)
  File "C:\Users\manue\anaconda3\lib\site-packages\ray\util\tracing\tracing_helper.py", line 466, in _resume_span
    return method(self, *_args, **_kwargs)
  File "C:\Users\manue\anaconda3\lib\site-packages\ray\tune\trainable\trainable.py", line 368, in train
    raise skipped from exception_cause(skipped)
  File "C:\Users\manue\anaconda3\lib\site-packages\ray\tune\trainable\function_trainable.py", line 337, in entrypoint
    return self._trainable_func(
  File "C:\Users\manue\anaconda3\lib\site-packages\ray\util\tracing\tracing_helper.py", line 466, in _resume_span
    return method(self, *_args, **_kwargs)
  File "C:\Users\manue\anaconda3\lib\site-packages\ray\tune\trainable\function_trainable.py", line 654, in _trainable_func
    output = fn()
  File "<timed exec>", line 28, in objective
  File "C:\Users\manue\anaconda3\lib\site-packages\ray\_private\client_mode_hook.py", line 105, in wrapper
    return func(*args, **kwargs)
  File "C:\Users\manue\anaconda3\lib\site-packages\ray\_private\worker.py", line 2369, in get
    raise ValueError(
ValueError: 'object_refs' must either be an ObjectRef or a list of ObjectRefs.
